2025-01-08 14:46:38 - INFO - Working on Que 09 ...
2025-01-08 14:46:39 - INFO - Requesting GPT to Replicate Question
2025-01-08 14:47:13 - INFO - HTTP Request: POST https://nw-tech-dev.openai.azure.com/openai/deployments/gpt-4o/chat/completions?api-version=2024-02-01 "HTTP/1.1 200 OK"
2025-01-08 14:47:13 - INFO - Question Replicated
2025-01-08 14:47:13 - INFO - Curating replica 1
2025-01-08 14:47:14 - INFO - Requesting GPT to generate solutions
2025-01-08 14:47:19 - INFO - HTTP Request: POST https://nw-tech-dev.openai.azure.com/openai/deployments/gpt-4o/chat/completions?api-version=2024-02-01 "HTTP/1.1 200 OK"
2025-01-08 14:47:19 - INFO - Solutions generated
2025-01-08 14:47:20 - INFO - Requesting GPT to generate test cases
2025-01-08 14:47:31 - ERROR - Traceback (most recent call last):
2025-01-08 14:47:31 - ERROR - File "D:\NxtWave\Coding-Question-Replicator\main.py", line 49, in <module>
2025-01-08 14:47:31 - ERROR - replicator.replicate(question_data.get('question'), question_data.get('file_name'), question_data.get('difficulty'), question_data.get('sub_topic'))
2025-01-08 14:47:31 - ERROR - File "D:\NxtWave\Coding-Question-Replicator\process_automation\replicator.py", line 59, in replicate
2025-01-08 14:47:31 - ERROR - response = self._generate_solutions(replicated_questions[key][0])
2025-01-08 14:47:31 - ERROR - ^
2025-01-08 14:47:31 - ERROR - ^
2025-01-08 14:47:31 - ERROR - ^
2025-01-08 14:47:31 - ERROR - ^
2025-01-08 14:47:31 - ERROR - ^
2025-01-08 14:47:31 - ERROR - ^
2025-01-08 14:47:31 - ERROR - ^
2025-01-08 14:47:31 - ERROR - ^
2025-01-08 14:47:31 - ERROR - ^
2025-01-08 14:47:31 - ERROR - ^
2025-01-08 14:47:31 - ERROR - ^
2025-01-08 14:47:31 - ERROR - ^
2025-01-08 14:47:31 - ERROR - ^
2025-01-08 14:47:31 - ERROR - ^
2025-01-08 14:47:31 - ERROR - ^
2025-01-08 14:47:31 - ERROR - ^
2025-01-08 14:47:31 - ERROR - ^
2025-01-08 14:47:31 - ERROR - ^
2025-01-08 14:47:31 - ERROR - ^
2025-01-08 14:47:31 - ERROR - ^
2025-01-08 14:47:31 - ERROR - ^
2025-01-08 14:47:31 - ERROR - ^
2025-01-08 14:47:31 - ERROR - ^
2025-01-08 14:47:31 - ERROR - ^
2025-01-08 14:47:31 - ERROR - ^
2025-01-08 14:47:31 - ERROR - ^
2025-01-08 14:47:31 - ERROR - ^
2025-01-08 14:47:31 - ERROR - ^
2025-01-08 14:47:31 - ERROR - ^
2025-01-08 14:47:31 - ERROR - ^
2025-01-08 14:47:31 - ERROR - ^
2025-01-08 14:47:31 - ERROR - ^
2025-01-08 14:47:31 - ERROR - ^
2025-01-08 14:47:31 - ERROR - ^
2025-01-08 14:47:31 - ERROR - ^
2025-01-08 14:47:31 - ERROR - ^
2025-01-08 14:47:31 - ERROR - ^
2025-01-08 14:47:31 - ERROR - ^
2025-01-08 14:47:31 - ERROR - ^
2025-01-08 14:47:31 - ERROR - ^
2025-01-08 14:47:31 - ERROR - ^
2025-01-08 14:47:31 - ERROR - ^
2025-01-08 14:47:31 - ERROR - ^
2025-01-08 14:47:31 - ERROR - ^
2025-01-08 14:47:31 - ERROR - ^
2025-01-08 14:47:31 - ERROR - ^
2025-01-08 14:47:31 - ERROR - ^
2025-01-08 14:47:31 - ERROR - ^
2025-01-08 14:47:31 - ERROR - ^
2025-01-08 14:47:31 - ERROR - ^
2025-01-08 14:47:31 - ERROR - ^
2025-01-08 14:47:31 - ERROR - ^
2025-01-08 14:47:31 - ERROR - ^
2025-01-08 14:47:31 - ERROR - ^
2025-01-08 14:47:31 - ERROR - File "D:\NxtWave\Coding-Question-Replicator\process_automation\replicator.py", line 28, in _generate_solutions
2025-01-08 14:47:31 - ERROR - response_testcases = agent.generate_testcases(self.MODEL_NAME, question)
2025-01-08 14:47:31 - ERROR - ^
2025-01-08 14:47:31 - ERROR - ^
2025-01-08 14:47:31 - ERROR - ^
2025-01-08 14:47:31 - ERROR - ^
2025-01-08 14:47:31 - ERROR - ^
2025-01-08 14:47:31 - ERROR - ^
2025-01-08 14:47:31 - ERROR - ^
2025-01-08 14:47:31 - ERROR - ^
2025-01-08 14:47:31 - ERROR - ^
2025-01-08 14:47:31 - ERROR - ^
2025-01-08 14:47:31 - ERROR - ^
2025-01-08 14:47:31 - ERROR - ^
2025-01-08 14:47:31 - ERROR - ^
2025-01-08 14:47:31 - ERROR - ^
2025-01-08 14:47:31 - ERROR - ^
2025-01-08 14:47:31 - ERROR - ^
2025-01-08 14:47:31 - ERROR - ^
2025-01-08 14:47:31 - ERROR - ^
2025-01-08 14:47:31 - ERROR - ^
2025-01-08 14:47:31 - ERROR - ^
2025-01-08 14:47:31 - ERROR - ^
2025-01-08 14:47:31 - ERROR - ^
2025-01-08 14:47:31 - ERROR - ^
2025-01-08 14:47:31 - ERROR - ^
2025-01-08 14:47:31 - ERROR - ^
2025-01-08 14:47:31 - ERROR - ^
2025-01-08 14:47:31 - ERROR - ^
2025-01-08 14:47:31 - ERROR - ^
2025-01-08 14:47:31 - ERROR - ^
2025-01-08 14:47:31 - ERROR - ^
2025-01-08 14:47:31 - ERROR - ^
2025-01-08 14:47:31 - ERROR - ^
2025-01-08 14:47:31 - ERROR - ^
2025-01-08 14:47:31 - ERROR - ^
2025-01-08 14:47:31 - ERROR - ^
2025-01-08 14:47:31 - ERROR - ^
2025-01-08 14:47:31 - ERROR - ^
2025-01-08 14:47:31 - ERROR - ^
2025-01-08 14:47:31 - ERROR - ^
2025-01-08 14:47:31 - ERROR - ^
2025-01-08 14:47:31 - ERROR - ^
2025-01-08 14:47:31 - ERROR - ^
2025-01-08 14:47:31 - ERROR - ^
2025-01-08 14:47:31 - ERROR - ^
2025-01-08 14:47:31 - ERROR - ^
2025-01-08 14:47:31 - ERROR - ^
2025-01-08 14:47:31 - ERROR - ^
2025-01-08 14:47:31 - ERROR - ^
2025-01-08 14:47:31 - ERROR - ^
2025-01-08 14:47:31 - ERROR - ^
2025-01-08 14:47:31 - ERROR - ^
2025-01-08 14:47:31 - ERROR - File "D:\NxtWave\Coding-Question-Replicator\process_automation\gpt_connect.py", line 35, in generate_testcases
2025-01-08 14:47:31 - ERROR - completion = self.client.chat.completions.create(
2025-01-08 14:47:31 - ERROR - ^
2025-01-08 14:47:31 - ERROR - ^
2025-01-08 14:47:31 - ERROR - ^
2025-01-08 14:47:31 - ERROR - ^
2025-01-08 14:47:31 - ERROR - ^
2025-01-08 14:47:31 - ERROR - ^
2025-01-08 14:47:31 - ERROR - ^
2025-01-08 14:47:31 - ERROR - ^
2025-01-08 14:47:31 - ERROR - ^
2025-01-08 14:47:31 - ERROR - ^
2025-01-08 14:47:31 - ERROR - ^
2025-01-08 14:47:31 - ERROR - ^
2025-01-08 14:47:31 - ERROR - ^
2025-01-08 14:47:31 - ERROR - ^
2025-01-08 14:47:31 - ERROR - ^
2025-01-08 14:47:31 - ERROR - ^
2025-01-08 14:47:31 - ERROR - ^
2025-01-08 14:47:31 - ERROR - ^
2025-01-08 14:47:31 - ERROR - ^
2025-01-08 14:47:31 - ERROR - ^
2025-01-08 14:47:31 - ERROR - ^
2025-01-08 14:47:31 - ERROR - ^
2025-01-08 14:47:31 - ERROR - ^
2025-01-08 14:47:31 - ERROR - ^
2025-01-08 14:47:31 - ERROR - ^
2025-01-08 14:47:31 - ERROR - ^
2025-01-08 14:47:31 - ERROR - ^
2025-01-08 14:47:31 - ERROR - ^
2025-01-08 14:47:31 - ERROR - ^
2025-01-08 14:47:31 - ERROR - ^
2025-01-08 14:47:31 - ERROR - ^
2025-01-08 14:47:31 - ERROR - ^
2025-01-08 14:47:31 - ERROR - ^
2025-01-08 14:47:31 - ERROR - ^
2025-01-08 14:47:31 - ERROR - ^
2025-01-08 14:47:31 - ERROR - ^
2025-01-08 14:47:31 - ERROR - File "D:\Compilers\Program Files\Python312\Lib\site-packages\openai\_utils\_utils.py", line 275, in wrapper
2025-01-08 14:47:31 - ERROR - return func(*args, **kwargs)
2025-01-08 14:47:31 - ERROR - ^
2025-01-08 14:47:31 - ERROR - ^
2025-01-08 14:47:31 - ERROR - ^
2025-01-08 14:47:31 - ERROR - ^
2025-01-08 14:47:31 - ERROR - ^
2025-01-08 14:47:31 - ERROR - ^
2025-01-08 14:47:31 - ERROR - ^
2025-01-08 14:47:31 - ERROR - ^
2025-01-08 14:47:31 - ERROR - ^
2025-01-08 14:47:31 - ERROR - ^
2025-01-08 14:47:31 - ERROR - ^
2025-01-08 14:47:31 - ERROR - ^
2025-01-08 14:47:31 - ERROR - ^
2025-01-08 14:47:31 - ERROR - ^
2025-01-08 14:47:31 - ERROR - ^
2025-01-08 14:47:31 - ERROR - ^
2025-01-08 14:47:31 - ERROR - ^
2025-01-08 14:47:31 - ERROR - ^
2025-01-08 14:47:31 - ERROR - ^
2025-01-08 14:47:31 - ERROR - ^
2025-01-08 14:47:31 - ERROR - ^
2025-01-08 14:47:31 - ERROR - File "D:\Compilers\Program Files\Python312\Lib\site-packages\openai\resources\chat\completions.py", line 859, in create
2025-01-08 14:47:31 - ERROR - return self._post(
2025-01-08 14:47:31 - ERROR - ^
2025-01-08 14:47:31 - ERROR - ^
2025-01-08 14:47:31 - ERROR - ^
2025-01-08 14:47:31 - ERROR - ^
2025-01-08 14:47:31 - ERROR - ^
2025-01-08 14:47:31 - ERROR - ^
2025-01-08 14:47:31 - ERROR - ^
2025-01-08 14:47:31 - ERROR - ^
2025-01-08 14:47:31 - ERROR - ^
2025-01-08 14:47:31 - ERROR - ^
2025-01-08 14:47:31 - ERROR - ^
2025-01-08 14:47:31 - ERROR - File "D:\Compilers\Program Files\Python312\Lib\site-packages\openai\_base_client.py", line 1280, in post
2025-01-08 14:47:31 - ERROR - return cast(ResponseT, self.request(cast_to, opts, stream=stream, stream_cls=stream_cls))
2025-01-08 14:47:31 - ERROR - ^
2025-01-08 14:47:31 - ERROR - ^
2025-01-08 14:47:31 - ERROR - ^
2025-01-08 14:47:31 - ERROR - ^
2025-01-08 14:47:31 - ERROR - ^
2025-01-08 14:47:31 - ERROR - ^
2025-01-08 14:47:31 - ERROR - ^
2025-01-08 14:47:31 - ERROR - ^
2025-01-08 14:47:31 - ERROR - ^
2025-01-08 14:47:31 - ERROR - ^
2025-01-08 14:47:31 - ERROR - ^
2025-01-08 14:47:31 - ERROR - ^
2025-01-08 14:47:31 - ERROR - ^
2025-01-08 14:47:31 - ERROR - ^
2025-01-08 14:47:31 - ERROR - ^
2025-01-08 14:47:31 - ERROR - ^
2025-01-08 14:47:31 - ERROR - ^
2025-01-08 14:47:31 - ERROR - ^
2025-01-08 14:47:31 - ERROR - ^
2025-01-08 14:47:31 - ERROR - ^
2025-01-08 14:47:31 - ERROR - ^
2025-01-08 14:47:31 - ERROR - ^
2025-01-08 14:47:31 - ERROR - ^
2025-01-08 14:47:31 - ERROR - ^
2025-01-08 14:47:31 - ERROR - ^
2025-01-08 14:47:31 - ERROR - ^
2025-01-08 14:47:31 - ERROR - ^
2025-01-08 14:47:31 - ERROR - ^
2025-01-08 14:47:31 - ERROR - ^
2025-01-08 14:47:31 - ERROR - ^
2025-01-08 14:47:31 - ERROR - ^
2025-01-08 14:47:31 - ERROR - ^
2025-01-08 14:47:31 - ERROR - ^
2025-01-08 14:47:31 - ERROR - ^
2025-01-08 14:47:31 - ERROR - ^
2025-01-08 14:47:31 - ERROR - ^
2025-01-08 14:47:31 - ERROR - ^
2025-01-08 14:47:31 - ERROR - ^
2025-01-08 14:47:31 - ERROR - ^
2025-01-08 14:47:31 - ERROR - ^
2025-01-08 14:47:31 - ERROR - ^
2025-01-08 14:47:31 - ERROR - ^
2025-01-08 14:47:31 - ERROR - ^
2025-01-08 14:47:31 - ERROR - ^
2025-01-08 14:47:31 - ERROR - ^
2025-01-08 14:47:31 - ERROR - ^
2025-01-08 14:47:31 - ERROR - ^
2025-01-08 14:47:31 - ERROR - ^
2025-01-08 14:47:31 - ERROR - ^
2025-01-08 14:47:31 - ERROR - ^
2025-01-08 14:47:31 - ERROR - ^
2025-01-08 14:47:31 - ERROR - ^
2025-01-08 14:47:31 - ERROR - ^
2025-01-08 14:47:31 - ERROR - ^
2025-01-08 14:47:31 - ERROR - ^
2025-01-08 14:47:31 - ERROR - ^
2025-01-08 14:47:31 - ERROR - ^
2025-01-08 14:47:31 - ERROR - ^
2025-01-08 14:47:31 - ERROR - ^
2025-01-08 14:47:31 - ERROR - ^
2025-01-08 14:47:31 - ERROR - ^
2025-01-08 14:47:31 - ERROR - ^
2025-01-08 14:47:31 - ERROR - ^
2025-01-08 14:47:31 - ERROR - ^
2025-01-08 14:47:31 - ERROR - ^
2025-01-08 14:47:31 - ERROR - File "D:\Compilers\Program Files\Python312\Lib\site-packages\openai\_base_client.py", line 957, in request
2025-01-08 14:47:31 - ERROR - return self._request(
2025-01-08 14:47:31 - ERROR - ^
2025-01-08 14:47:31 - ERROR - ^
2025-01-08 14:47:31 - ERROR - ^
2025-01-08 14:47:31 - ERROR - ^
2025-01-08 14:47:31 - ERROR - ^
2025-01-08 14:47:31 - ERROR - ^
2025-01-08 14:47:31 - ERROR - ^
2025-01-08 14:47:31 - ERROR - ^
2025-01-08 14:47:31 - ERROR - ^
2025-01-08 14:47:31 - ERROR - ^
2025-01-08 14:47:31 - ERROR - ^
2025-01-08 14:47:31 - ERROR - ^
2025-01-08 14:47:31 - ERROR - ^
2025-01-08 14:47:31 - ERROR - ^
2025-01-08 14:47:31 - ERROR - File "D:\Compilers\Program Files\Python312\Lib\site-packages\openai\_base_client.py", line 993, in _request
2025-01-08 14:47:31 - ERROR - response = self._client.send(
2025-01-08 14:47:31 - ERROR - ^
2025-01-08 14:47:31 - ERROR - ^
2025-01-08 14:47:31 - ERROR - ^
2025-01-08 14:47:31 - ERROR - ^
2025-01-08 14:47:31 - ERROR - ^
2025-01-08 14:47:31 - ERROR - ^
2025-01-08 14:47:31 - ERROR - ^
2025-01-08 14:47:31 - ERROR - ^
2025-01-08 14:47:31 - ERROR - ^
2025-01-08 14:47:31 - ERROR - ^
2025-01-08 14:47:31 - ERROR - ^
2025-01-08 14:47:31 - ERROR - ^
2025-01-08 14:47:31 - ERROR - ^
2025-01-08 14:47:31 - ERROR - ^
2025-01-08 14:47:31 - ERROR - ^
2025-01-08 14:47:31 - ERROR - ^
2025-01-08 14:47:31 - ERROR - ^
2025-01-08 14:47:31 - ERROR - ^
2025-01-08 14:47:31 - ERROR - File "D:\Compilers\Program Files\Python312\Lib\site-packages\httpx\_client.py", line 914, in send
2025-01-08 14:47:31 - ERROR - response = self._send_handling_auth(
2025-01-08 14:47:31 - ERROR - ^
2025-01-08 14:47:31 - ERROR - ^
2025-01-08 14:47:31 - ERROR - ^
2025-01-08 14:47:31 - ERROR - ^
2025-01-08 14:47:31 - ERROR - ^
2025-01-08 14:47:31 - ERROR - ^
2025-01-08 14:47:31 - ERROR - ^
2025-01-08 14:47:31 - ERROR - ^
2025-01-08 14:47:31 - ERROR - ^
2025-01-08 14:47:31 - ERROR - ^
2025-01-08 14:47:31 - ERROR - ^
2025-01-08 14:47:31 - ERROR - ^
2025-01-08 14:47:31 - ERROR - ^
2025-01-08 14:47:31 - ERROR - ^
2025-01-08 14:47:31 - ERROR - ^
2025-01-08 14:47:31 - ERROR - ^
2025-01-08 14:47:31 - ERROR - ^
2025-01-08 14:47:31 - ERROR - ^
2025-01-08 14:47:31 - ERROR - ^
2025-01-08 14:47:31 - ERROR - ^
2025-01-08 14:47:31 - ERROR - ^
2025-01-08 14:47:31 - ERROR - ^
2025-01-08 14:47:31 - ERROR - ^
2025-01-08 14:47:31 - ERROR - ^
2025-01-08 14:47:31 - ERROR - ^
2025-01-08 14:47:31 - ERROR - File "D:\Compilers\Program Files\Python312\Lib\site-packages\httpx\_client.py", line 942, in _send_handling_auth
2025-01-08 14:47:31 - ERROR - response = self._send_handling_redirects(
2025-01-08 14:47:31 - ERROR - ^
2025-01-08 14:47:31 - ERROR - ^
2025-01-08 14:47:31 - ERROR - ^
2025-01-08 14:47:31 - ERROR - ^
2025-01-08 14:47:31 - ERROR - ^
2025-01-08 14:47:31 - ERROR - ^
2025-01-08 14:47:31 - ERROR - ^
2025-01-08 14:47:31 - ERROR - ^
2025-01-08 14:47:31 - ERROR - ^
2025-01-08 14:47:31 - ERROR - ^
2025-01-08 14:47:31 - ERROR - ^
2025-01-08 14:47:31 - ERROR - ^
2025-01-08 14:47:31 - ERROR - ^
2025-01-08 14:47:31 - ERROR - ^
2025-01-08 14:47:31 - ERROR - ^
2025-01-08 14:47:31 - ERROR - ^
2025-01-08 14:47:31 - ERROR - ^
2025-01-08 14:47:31 - ERROR - ^
2025-01-08 14:47:31 - ERROR - ^
2025-01-08 14:47:31 - ERROR - ^
2025-01-08 14:47:31 - ERROR - ^
2025-01-08 14:47:31 - ERROR - ^
2025-01-08 14:47:31 - ERROR - ^
2025-01-08 14:47:31 - ERROR - ^
2025-01-08 14:47:31 - ERROR - ^
2025-01-08 14:47:31 - ERROR - ^
2025-01-08 14:47:31 - ERROR - ^
2025-01-08 14:47:31 - ERROR - ^
2025-01-08 14:47:31 - ERROR - ^
2025-01-08 14:47:31 - ERROR - ^
2025-01-08 14:47:31 - ERROR - File "D:\Compilers\Program Files\Python312\Lib\site-packages\httpx\_client.py", line 979, in _send_handling_redirects
2025-01-08 14:47:31 - ERROR - response = self._send_single_request(request)
2025-01-08 14:47:31 - ERROR - ^
2025-01-08 14:47:31 - ERROR - ^
2025-01-08 14:47:31 - ERROR - ^
2025-01-08 14:47:31 - ERROR - ^
2025-01-08 14:47:31 - ERROR - ^
2025-01-08 14:47:31 - ERROR - ^
2025-01-08 14:47:31 - ERROR - ^
2025-01-08 14:47:31 - ERROR - ^
2025-01-08 14:47:31 - ERROR - ^
2025-01-08 14:47:31 - ERROR - ^
2025-01-08 14:47:31 - ERROR - ^
2025-01-08 14:47:31 - ERROR - ^
2025-01-08 14:47:31 - ERROR - ^
2025-01-08 14:47:31 - ERROR - ^
2025-01-08 14:47:31 - ERROR - ^
2025-01-08 14:47:31 - ERROR - ^
2025-01-08 14:47:31 - ERROR - ^
2025-01-08 14:47:31 - ERROR - ^
2025-01-08 14:47:31 - ERROR - ^
2025-01-08 14:47:31 - ERROR - ^
2025-01-08 14:47:31 - ERROR - ^
2025-01-08 14:47:31 - ERROR - ^
2025-01-08 14:47:31 - ERROR - ^
2025-01-08 14:47:31 - ERROR - ^
2025-01-08 14:47:31 - ERROR - ^
2025-01-08 14:47:31 - ERROR - ^
2025-01-08 14:47:31 - ERROR - ^
2025-01-08 14:47:31 - ERROR - ^
2025-01-08 14:47:31 - ERROR - ^
2025-01-08 14:47:31 - ERROR - ^
2025-01-08 14:47:31 - ERROR - ^
2025-01-08 14:47:31 - ERROR - ^
2025-01-08 14:47:31 - ERROR - ^
2025-01-08 14:47:31 - ERROR - ^
2025-01-08 14:47:31 - ERROR - File "D:\Compilers\Program Files\Python312\Lib\site-packages\httpx\_client.py", line 1014, in _send_single_request
2025-01-08 14:47:31 - ERROR - response = transport.handle_request(request)
2025-01-08 14:47:31 - ERROR - ^
2025-01-08 14:47:31 - ERROR - ^
2025-01-08 14:47:31 - ERROR - ^
2025-01-08 14:47:31 - ERROR - ^
2025-01-08 14:47:31 - ERROR - ^
2025-01-08 14:47:31 - ERROR - ^
2025-01-08 14:47:31 - ERROR - ^
2025-01-08 14:47:31 - ERROR - ^
2025-01-08 14:47:31 - ERROR - ^
2025-01-08 14:47:31 - ERROR - ^
2025-01-08 14:47:31 - ERROR - ^
2025-01-08 14:47:31 - ERROR - ^
2025-01-08 14:47:31 - ERROR - ^
2025-01-08 14:47:31 - ERROR - ^
2025-01-08 14:47:31 - ERROR - ^
2025-01-08 14:47:31 - ERROR - ^
2025-01-08 14:47:31 - ERROR - ^
2025-01-08 14:47:31 - ERROR - ^
2025-01-08 14:47:31 - ERROR - ^
2025-01-08 14:47:31 - ERROR - ^
2025-01-08 14:47:31 - ERROR - ^
2025-01-08 14:47:31 - ERROR - ^
2025-01-08 14:47:31 - ERROR - ^
2025-01-08 14:47:31 - ERROR - ^
2025-01-08 14:47:31 - ERROR - ^
2025-01-08 14:47:31 - ERROR - ^
2025-01-08 14:47:31 - ERROR - ^
2025-01-08 14:47:31 - ERROR - ^
2025-01-08 14:47:31 - ERROR - ^
2025-01-08 14:47:31 - ERROR - ^
2025-01-08 14:47:31 - ERROR - ^
2025-01-08 14:47:31 - ERROR - ^
2025-01-08 14:47:31 - ERROR - ^
2025-01-08 14:47:31 - ERROR - File "D:\Compilers\Program Files\Python312\Lib\site-packages\httpx\_transports\default.py", line 250, in handle_request
2025-01-08 14:47:31 - ERROR - resp = self._pool.handle_request(req)
2025-01-08 14:47:31 - ERROR - ^
2025-01-08 14:47:31 - ERROR - ^
2025-01-08 14:47:31 - ERROR - ^
2025-01-08 14:47:31 - ERROR - ^
2025-01-08 14:47:31 - ERROR - ^
2025-01-08 14:47:31 - ERROR - ^
2025-01-08 14:47:31 - ERROR - ^
2025-01-08 14:47:31 - ERROR - ^
2025-01-08 14:47:31 - ERROR - ^
2025-01-08 14:47:31 - ERROR - ^
2025-01-08 14:47:31 - ERROR - ^
2025-01-08 14:47:31 - ERROR - ^
2025-01-08 14:47:31 - ERROR - ^
2025-01-08 14:47:31 - ERROR - ^
2025-01-08 14:47:31 - ERROR - ^
2025-01-08 14:47:31 - ERROR - ^
2025-01-08 14:47:31 - ERROR - ^
2025-01-08 14:47:31 - ERROR - ^
2025-01-08 14:47:31 - ERROR - ^
2025-01-08 14:47:31 - ERROR - ^
2025-01-08 14:47:31 - ERROR - ^
2025-01-08 14:47:31 - ERROR - ^
2025-01-08 14:47:31 - ERROR - ^
2025-01-08 14:47:31 - ERROR - ^
2025-01-08 14:47:31 - ERROR - ^
2025-01-08 14:47:31 - ERROR - ^
2025-01-08 14:47:31 - ERROR - ^
2025-01-08 14:47:31 - ERROR - ^
2025-01-08 14:47:31 - ERROR - ^
2025-01-08 14:47:31 - ERROR - ^
2025-01-08 14:47:31 - ERROR - File "D:\Compilers\Program Files\Python312\Lib\site-packages\httpcore\_sync\connection_pool.py", line 256, in handle_request
2025-01-08 14:47:31 - ERROR - raise exc from None
2025-01-08 14:47:31 - ERROR - File "D:\Compilers\Program Files\Python312\Lib\site-packages\httpcore\_sync\connection_pool.py", line 236, in handle_request
2025-01-08 14:47:31 - ERROR - response = connection.handle_request(
2025-01-08 14:47:31 - ERROR - ^
2025-01-08 14:47:31 - ERROR - ^
2025-01-08 14:47:31 - ERROR - ^
2025-01-08 14:47:31 - ERROR - ^
2025-01-08 14:47:31 - ERROR - ^
2025-01-08 14:47:31 - ERROR - ^
2025-01-08 14:47:31 - ERROR - ^
2025-01-08 14:47:31 - ERROR - ^
2025-01-08 14:47:31 - ERROR - ^
2025-01-08 14:47:31 - ERROR - ^
2025-01-08 14:47:31 - ERROR - ^
2025-01-08 14:47:31 - ERROR - ^
2025-01-08 14:47:31 - ERROR - ^
2025-01-08 14:47:31 - ERROR - ^
2025-01-08 14:47:31 - ERROR - ^
2025-01-08 14:47:31 - ERROR - ^
2025-01-08 14:47:31 - ERROR - ^
2025-01-08 14:47:31 - ERROR - ^
2025-01-08 14:47:31 - ERROR - ^
2025-01-08 14:47:31 - ERROR - ^
2025-01-08 14:47:31 - ERROR - ^
2025-01-08 14:47:31 - ERROR - ^
2025-01-08 14:47:31 - ERROR - ^
2025-01-08 14:47:31 - ERROR - ^
2025-01-08 14:47:31 - ERROR - ^
2025-01-08 14:47:31 - ERROR - ^
2025-01-08 14:47:31 - ERROR - File "D:\Compilers\Program Files\Python312\Lib\site-packages\httpcore\_sync\connection.py", line 103, in handle_request
2025-01-08 14:47:31 - ERROR - return self._connection.handle_request(request)
2025-01-08 14:47:31 - ERROR - ^
2025-01-08 14:47:31 - ERROR - ^
2025-01-08 14:47:31 - ERROR - ^
2025-01-08 14:47:31 - ERROR - ^
2025-01-08 14:47:31 - ERROR - ^
2025-01-08 14:47:31 - ERROR - ^
2025-01-08 14:47:31 - ERROR - ^
2025-01-08 14:47:31 - ERROR - ^
2025-01-08 14:47:31 - ERROR - ^
2025-01-08 14:47:31 - ERROR - ^
2025-01-08 14:47:31 - ERROR - ^
2025-01-08 14:47:31 - ERROR - ^
2025-01-08 14:47:31 - ERROR - ^
2025-01-08 14:47:31 - ERROR - ^
2025-01-08 14:47:31 - ERROR - ^
2025-01-08 14:47:31 - ERROR - ^
2025-01-08 14:47:31 - ERROR - ^
2025-01-08 14:47:31 - ERROR - ^
2025-01-08 14:47:31 - ERROR - ^
2025-01-08 14:47:31 - ERROR - ^
2025-01-08 14:47:31 - ERROR - ^
2025-01-08 14:47:31 - ERROR - ^
2025-01-08 14:47:31 - ERROR - ^
2025-01-08 14:47:31 - ERROR - ^
2025-01-08 14:47:31 - ERROR - ^
2025-01-08 14:47:31 - ERROR - ^
2025-01-08 14:47:31 - ERROR - ^
2025-01-08 14:47:31 - ERROR - ^
2025-01-08 14:47:31 - ERROR - ^
2025-01-08 14:47:31 - ERROR - ^
2025-01-08 14:47:31 - ERROR - ^
2025-01-08 14:47:31 - ERROR - ^
2025-01-08 14:47:31 - ERROR - ^
2025-01-08 14:47:31 - ERROR - ^
2025-01-08 14:47:31 - ERROR - ^
2025-01-08 14:47:31 - ERROR - ^
2025-01-08 14:47:31 - ERROR - ^
2025-01-08 14:47:31 - ERROR - ^
2025-01-08 14:47:31 - ERROR - ^
2025-01-08 14:47:31 - ERROR - ^
2025-01-08 14:47:31 - ERROR - File "D:\Compilers\Program Files\Python312\Lib\site-packages\httpcore\_sync\http11.py", line 136, in handle_request
2025-01-08 14:47:31 - ERROR - raise exc
2025-01-08 14:47:31 - ERROR - File "D:\Compilers\Program Files\Python312\Lib\site-packages\httpcore\_sync\http11.py", line 106, in handle_request
2025-01-08 14:47:31 - ERROR - ) = self._receive_response_headers(**kwargs)
2025-01-08 14:47:31 - ERROR - ^
2025-01-08 14:47:31 - ERROR - ^
2025-01-08 14:47:31 - ERROR - ^
2025-01-08 14:47:31 - ERROR - ^
2025-01-08 14:47:31 - ERROR - ^
2025-01-08 14:47:31 - ERROR - ^
2025-01-08 14:47:31 - ERROR - ^
2025-01-08 14:47:31 - ERROR - ^
2025-01-08 14:47:31 - ERROR - ^
2025-01-08 14:47:31 - ERROR - ^
2025-01-08 14:47:31 - ERROR - ^
2025-01-08 14:47:31 - ERROR - ^
2025-01-08 14:47:31 - ERROR - ^
2025-01-08 14:47:31 - ERROR - ^
2025-01-08 14:47:31 - ERROR - ^
2025-01-08 14:47:31 - ERROR - ^
2025-01-08 14:47:31 - ERROR - ^
2025-01-08 14:47:31 - ERROR - ^
2025-01-08 14:47:31 - ERROR - ^
2025-01-08 14:47:31 - ERROR - ^
2025-01-08 14:47:31 - ERROR - ^
2025-01-08 14:47:31 - ERROR - ^
2025-01-08 14:47:31 - ERROR - ^
2025-01-08 14:47:31 - ERROR - ^
2025-01-08 14:47:31 - ERROR - ^
2025-01-08 14:47:31 - ERROR - ^
2025-01-08 14:47:31 - ERROR - ^
2025-01-08 14:47:31 - ERROR - ^
2025-01-08 14:47:31 - ERROR - ^
2025-01-08 14:47:31 - ERROR - ^
2025-01-08 14:47:31 - ERROR - ^
2025-01-08 14:47:31 - ERROR - ^
2025-01-08 14:47:31 - ERROR - ^
2025-01-08 14:47:31 - ERROR - ^
2025-01-08 14:47:31 - ERROR - ^
2025-01-08 14:47:31 - ERROR - ^
2025-01-08 14:47:31 - ERROR - ^
2025-01-08 14:47:31 - ERROR - ^
2025-01-08 14:47:31 - ERROR - ^
2025-01-08 14:47:31 - ERROR - ^
2025-01-08 14:47:31 - ERROR - File "D:\Compilers\Program Files\Python312\Lib\site-packages\httpcore\_sync\http11.py", line 177, in _receive_response_headers
2025-01-08 14:47:31 - ERROR - event = self._receive_event(timeout=timeout)
2025-01-08 14:47:31 - ERROR - ^
2025-01-08 14:47:31 - ERROR - ^
2025-01-08 14:47:31 - ERROR - ^
2025-01-08 14:47:31 - ERROR - ^
2025-01-08 14:47:31 - ERROR - ^
2025-01-08 14:47:31 - ERROR - ^
2025-01-08 14:47:31 - ERROR - ^
2025-01-08 14:47:31 - ERROR - ^
2025-01-08 14:47:31 - ERROR - ^
2025-01-08 14:47:31 - ERROR - ^
2025-01-08 14:47:31 - ERROR - ^
2025-01-08 14:47:31 - ERROR - ^
2025-01-08 14:47:31 - ERROR - ^
2025-01-08 14:47:31 - ERROR - ^
2025-01-08 14:47:31 - ERROR - ^
2025-01-08 14:47:31 - ERROR - ^
2025-01-08 14:47:31 - ERROR - ^
2025-01-08 14:47:31 - ERROR - ^
2025-01-08 14:47:31 - ERROR - ^
2025-01-08 14:47:31 - ERROR - ^
2025-01-08 14:47:31 - ERROR - ^
2025-01-08 14:47:31 - ERROR - ^
2025-01-08 14:47:31 - ERROR - ^
2025-01-08 14:47:31 - ERROR - ^
2025-01-08 14:47:31 - ERROR - ^
2025-01-08 14:47:31 - ERROR - ^
2025-01-08 14:47:31 - ERROR - ^
2025-01-08 14:47:31 - ERROR - ^
2025-01-08 14:47:31 - ERROR - ^
2025-01-08 14:47:31 - ERROR - ^
2025-01-08 14:47:31 - ERROR - ^
2025-01-08 14:47:31 - ERROR - ^
2025-01-08 14:47:31 - ERROR - ^
2025-01-08 14:47:31 - ERROR - ^
2025-01-08 14:47:31 - ERROR - ^
2025-01-08 14:47:31 - ERROR - ^
2025-01-08 14:47:31 - ERROR - File "D:\Compilers\Program Files\Python312\Lib\site-packages\httpcore\_sync\http11.py", line 217, in _receive_event
2025-01-08 14:47:31 - ERROR - data = self._network_stream.read(
2025-01-08 14:47:31 - ERROR - ^
2025-01-08 14:47:31 - ERROR - ^
2025-01-08 14:47:31 - ERROR - ^
2025-01-08 14:47:31 - ERROR - ^
2025-01-08 14:47:31 - ERROR - ^
2025-01-08 14:47:31 - ERROR - ^
2025-01-08 14:47:31 - ERROR - ^
2025-01-08 14:47:31 - ERROR - ^
2025-01-08 14:47:31 - ERROR - ^
2025-01-08 14:47:31 - ERROR - ^
2025-01-08 14:47:31 - ERROR - ^
2025-01-08 14:47:31 - ERROR - ^
2025-01-08 14:47:31 - ERROR - ^
2025-01-08 14:47:31 - ERROR - ^
2025-01-08 14:47:31 - ERROR - ^
2025-01-08 14:47:31 - ERROR - ^
2025-01-08 14:47:31 - ERROR - ^
2025-01-08 14:47:31 - ERROR - ^
2025-01-08 14:47:31 - ERROR - ^
2025-01-08 14:47:31 - ERROR - ^
2025-01-08 14:47:31 - ERROR - ^
2025-01-08 14:47:31 - ERROR - ^
2025-01-08 14:47:31 - ERROR - ^
2025-01-08 14:47:31 - ERROR - ^
2025-01-08 14:47:31 - ERROR - ^
2025-01-08 14:47:31 - ERROR - ^
2025-01-08 14:47:31 - ERROR - File "D:\Compilers\Program Files\Python312\Lib\site-packages\httpcore\_backends\sync.py", line 128, in read
2025-01-08 14:47:31 - ERROR - return self._sock.recv(max_bytes)
2025-01-08 14:47:31 - ERROR - ^
2025-01-08 14:47:31 - ERROR - ^
2025-01-08 14:47:31 - ERROR - ^
2025-01-08 14:47:31 - ERROR - ^
2025-01-08 14:47:31 - ERROR - ^
2025-01-08 14:47:31 - ERROR - ^
2025-01-08 14:47:31 - ERROR - ^
2025-01-08 14:47:31 - ERROR - ^
2025-01-08 14:47:31 - ERROR - ^
2025-01-08 14:47:31 - ERROR - ^
2025-01-08 14:47:31 - ERROR - ^
2025-01-08 14:47:31 - ERROR - ^
2025-01-08 14:47:31 - ERROR - ^
2025-01-08 14:47:31 - ERROR - ^
2025-01-08 14:47:31 - ERROR - ^
2025-01-08 14:47:31 - ERROR - ^
2025-01-08 14:47:31 - ERROR - ^
2025-01-08 14:47:31 - ERROR - ^
2025-01-08 14:47:31 - ERROR - ^
2025-01-08 14:47:31 - ERROR - ^
2025-01-08 14:47:31 - ERROR - ^
2025-01-08 14:47:31 - ERROR - ^
2025-01-08 14:47:31 - ERROR - ^
2025-01-08 14:47:31 - ERROR - ^
2025-01-08 14:47:31 - ERROR - ^
2025-01-08 14:47:31 - ERROR - ^
2025-01-08 14:47:31 - ERROR - File "D:\Compilers\Program Files\Python312\Lib\ssl.py", line 1232, in recv
2025-01-08 14:47:31 - ERROR - return self.read(buflen)
2025-01-08 14:47:31 - ERROR - ^
2025-01-08 14:47:31 - ERROR - ^
2025-01-08 14:47:31 - ERROR - ^
2025-01-08 14:47:31 - ERROR - ^
2025-01-08 14:47:31 - ERROR - ^
2025-01-08 14:47:31 - ERROR - ^
2025-01-08 14:47:31 - ERROR - ^
2025-01-08 14:47:31 - ERROR - ^
2025-01-08 14:47:31 - ERROR - ^
2025-01-08 14:47:31 - ERROR - ^
2025-01-08 14:47:31 - ERROR - ^
2025-01-08 14:47:31 - ERROR - ^
2025-01-08 14:47:31 - ERROR - ^
2025-01-08 14:47:31 - ERROR - ^
2025-01-08 14:47:31 - ERROR - ^
2025-01-08 14:47:31 - ERROR - ^
2025-01-08 14:47:31 - ERROR - ^
2025-01-08 14:47:31 - ERROR - File "D:\Compilers\Program Files\Python312\Lib\ssl.py", line 1105, in read
2025-01-08 14:47:31 - ERROR - return self._sslobj.read(len)
2025-01-08 14:47:31 - ERROR - ^
2025-01-08 14:47:31 - ERROR - ^
2025-01-08 14:47:31 - ERROR - ^
2025-01-08 14:47:31 - ERROR - ^
2025-01-08 14:47:31 - ERROR - ^
2025-01-08 14:47:31 - ERROR - ^
2025-01-08 14:47:31 - ERROR - ^
2025-01-08 14:47:31 - ERROR - ^
2025-01-08 14:47:31 - ERROR - ^
2025-01-08 14:47:31 - ERROR - ^
2025-01-08 14:47:31 - ERROR - ^
2025-01-08 14:47:31 - ERROR - ^
2025-01-08 14:47:31 - ERROR - ^
2025-01-08 14:47:31 - ERROR - ^
2025-01-08 14:47:31 - ERROR - ^
2025-01-08 14:47:31 - ERROR - ^
2025-01-08 14:47:31 - ERROR - ^
2025-01-08 14:47:31 - ERROR - ^
2025-01-08 14:47:31 - ERROR - ^
2025-01-08 14:47:31 - ERROR - ^
2025-01-08 14:47:31 - ERROR - ^
2025-01-08 14:47:31 - ERROR - ^
2025-01-08 14:47:31 - ERROR - KeyboardInterrupt
